[2025-08-03 17:11:31 +0000] [12] [ERROR] Exception in worker process
Traceback (most recent call last):
  File "/usr/local/lib/python3.9/site-packages/gunicorn/arbiter.py", line 583, in spawn_worker
    worker.init_process()
  File "/usr/local/lib/python3.9/site-packages/gunicorn/workers/base.py", line 129, in init_process
    self.load_wsgi()
  File "/usr/local/lib/python3.9/site-packages/gunicorn/workers/base.py", line 138, in load_wsgi
    self.wsgi = self.app.wsgi()
  File "/usr/local/lib/python3.9/site-packages/gunicorn/app/base.py", line 67, in wsgi
    self.callable = self.load()
  File "/usr/local/lib/python3.9/site-packages/psiturk/experiment_server.py", line 48, in load
    return util.import_app("psiturk.experiment:app")
  File "/usr/local/lib/python3.9/site-packages/gunicorn/util.py", line 350, in import_app
    __import__(module)
  File "/usr/local/lib/python3.9/site-packages/psiturk/experiment.py", line 30, in <module>
    from .db import db_session, init_db
  File "/usr/local/lib/python3.9/site-packages/psiturk/db.py", line 28, in <module>
    engine = create_engine(DATABASE, echo=False, pool_recycle=3600)
  File "/usr/local/lib/python3.9/site-packages/sqlalchemy/engine/__init__.py", line 435, in create_engine
    return strategy.create(*args, **kwargs)
  File "/usr/local/lib/python3.9/site-packages/sqlalchemy/engine/strategies.py", line 54, in create
    u = url.make_url(name_or_url)
  File "/usr/local/lib/python3.9/site-packages/sqlalchemy/engine/url.py", line 229, in make_url
    return _parse_rfc1738_args(name_or_url)
  File "/usr/local/lib/python3.9/site-packages/sqlalchemy/engine/url.py", line 290, in _parse_rfc1738_args
    raise exc.ArgumentError(
sqlalchemy.exc.ArgumentError: Could not parse rfc1738 URL from string ''
[2025-08-03 17:11:31 +0000] [11] [ERROR] Exception in worker process
Traceback (most recent call last):
  File "/usr/local/lib/python3.9/site-packages/gunicorn/arbiter.py", line 583, in spawn_worker
    worker.init_process()
  File "/usr/local/lib/python3.9/site-packages/gunicorn/workers/base.py", line 129, in init_process
    self.load_wsgi()
  File "/usr/local/lib/python3.9/site-packages/gunicorn/workers/base.py", line 138, in load_wsgi
    self.wsgi = self.app.wsgi()
  File "/usr/local/lib/python3.9/site-packages/gunicorn/app/base.py", line 67, in wsgi
    self.callable = self.load()
  File "/usr/local/lib/python3.9/site-packages/psiturk/experiment_server.py", line 48, in load
    return util.import_app("psiturk.experiment:app")
  File "/usr/local/lib/python3.9/site-packages/gunicorn/util.py", line 350, in import_app
    __import__(module)
  File "/usr/local/lib/python3.9/site-packages/psiturk/experiment.py", line 30, in <module>
    from .db import db_session, init_db
  File "/usr/local/lib/python3.9/site-packages/psiturk/db.py", line 28, in <module>
    engine = create_engine(DATABASE, echo=False, pool_recycle=3600)
  File "/usr/local/lib/python3.9/site-packages/sqlalchemy/engine/__init__.py", line 435, in create_engine
    return strategy.create(*args, **kwargs)
  File "/usr/local/lib/python3.9/site-packages/sqlalchemy/engine/strategies.py", line 54, in create
    u = url.make_url(name_or_url)
  File "/usr/local/lib/python3.9/site-packages/sqlalchemy/engine/url.py", line 229, in make_url
    return _parse_rfc1738_args(name_or_url)
  File "/usr/local/lib/python3.9/site-packages/sqlalchemy/engine/url.py", line 290, in _parse_rfc1738_args
    raise exc.ArgumentError(
sqlalchemy.exc.ArgumentError: Could not parse rfc1738 URL from string ''
[2025-08-03 17:11:31 +0000] [10] [ERROR] Exception in worker process
Traceback (most recent call last):
  File "/usr/local/lib/python3.9/site-packages/gunicorn/arbiter.py", line 583, in spawn_worker
    worker.init_process()
  File "/usr/local/lib/python3.9/site-packages/gunicorn/workers/base.py", line 129, in init_process
    self.load_wsgi()
  File "/usr/local/lib/python3.9/site-packages/gunicorn/workers/base.py", line 138, in load_wsgi
    self.wsgi = self.app.wsgi()
  File "/usr/local/lib/python3.9/site-packages/gunicorn/app/base.py", line 67, in wsgi
    self.callable = self.load()
  File "/usr/local/lib/python3.9/site-packages/psiturk/experiment_server.py", line 48, in load
    return util.import_app("psiturk.experiment:app")
  File "/usr/local/lib/python3.9/site-packages/gunicorn/util.py", line 350, in import_app
    __import__(module)
  File "/usr/local/lib/python3.9/site-packages/psiturk/experiment.py", line 30, in <module>
    from .db import db_session, init_db
  File "/usr/local/lib/python3.9/site-packages/psiturk/db.py", line 28, in <module>
    engine = create_engine(DATABASE, echo=False, pool_recycle=3600)
  File "/usr/local/lib/python3.9/site-packages/sqlalchemy/engine/__init__.py", line 435, in create_engine
    return strategy.create(*args, **kwargs)
  File "/usr/local/lib/python3.9/site-packages/sqlalchemy/engine/strategies.py", line 54, in create
    u = url.make_url(name_or_url)
  File "/usr/local/lib/python3.9/site-packages/sqlalchemy/engine/url.py", line 229, in make_url
    return _parse_rfc1738_args(name_or_url)
  File "/usr/local/lib/python3.9/site-packages/sqlalchemy/engine/url.py", line 290, in _parse_rfc1738_args
    raise exc.ArgumentError(
sqlalchemy.exc.ArgumentError: Could not parse rfc1738 URL from string ''
[2025-08-03 17:11:31 +0000] [13] [ERROR] Exception in worker process
Traceback (most recent call last):
  File "/usr/local/lib/python3.9/site-packages/gunicorn/arbiter.py", line 583, in spawn_worker
    worker.init_process()
  File "/usr/local/lib/python3.9/site-packages/gunicorn/workers/base.py", line 129, in init_process
    self.load_wsgi()
  File "/usr/local/lib/python3.9/site-packages/gunicorn/workers/base.py", line 138, in load_wsgi
    self.wsgi = self.app.wsgi()
  File "/usr/local/lib/python3.9/site-packages/gunicorn/app/base.py", line 67, in wsgi
    self.callable = self.load()
  File "/usr/local/lib/python3.9/site-packages/psiturk/experiment_server.py", line 48, in load
    return util.import_app("psiturk.experiment:app")
  File "/usr/local/lib/python3.9/site-packages/gunicorn/util.py", line 350, in import_app
    __import__(module)
  File "/usr/local/lib/python3.9/site-packages/psiturk/experiment.py", line 30, in <module>
    from .db import db_session, init_db
  File "/usr/local/lib/python3.9/site-packages/psiturk/db.py", line 28, in <module>
    engine = create_engine(DATABASE, echo=False, pool_recycle=3600)
  File "/usr/local/lib/python3.9/site-packages/sqlalchemy/engine/__init__.py", line 435, in create_engine
    return strategy.create(*args, **kwargs)
  File "/usr/local/lib/python3.9/site-packages/sqlalchemy/engine/strategies.py", line 54, in create
    u = url.make_url(name_or_url)
  File "/usr/local/lib/python3.9/site-packages/sqlalchemy/engine/url.py", line 229, in make_url
    return _parse_rfc1738_args(name_or_url)
  File "/usr/local/lib/python3.9/site-packages/sqlalchemy/engine/url.py", line 290, in _parse_rfc1738_args
    raise exc.ArgumentError(
sqlalchemy.exc.ArgumentError: Could not parse rfc1738 URL from string ''
[2025-08-03 17:11:31 +0000] [17] [ERROR] Exception in worker process
Traceback (most recent call last):
  File "/usr/local/lib/python3.9/site-packages/gunicorn/arbiter.py", line 583, in spawn_worker
    worker.init_process()
  File "/usr/local/lib/python3.9/site-packages/gunicorn/workers/base.py", line 129, in init_process
    self.load_wsgi()
  File "/usr/local/lib/python3.9/site-packages/gunicorn/workers/base.py", line 138, in load_wsgi
    self.wsgi = self.app.wsgi()
  File "/usr/local/lib/python3.9/site-packages/gunicorn/app/base.py", line 67, in wsgi
    self.callable = self.load()
  File "/usr/local/lib/python3.9/site-packages/psiturk/experiment_server.py", line 48, in load
    return util.import_app("psiturk.experiment:app")
  File "/usr/local/lib/python3.9/site-packages/gunicorn/util.py", line 350, in import_app
    __import__(module)
  File "/usr/local/lib/python3.9/site-packages/psiturk/experiment.py", line 30, in <module>
    from .db import db_session, init_db
  File "/usr/local/lib/python3.9/site-packages/psiturk/db.py", line 28, in <module>
    engine = create_engine(DATABASE, echo=False, pool_recycle=3600)
  File "/usr/local/lib/python3.9/site-packages/sqlalchemy/engine/__init__.py", line 435, in create_engine
    return strategy.create(*args, **kwargs)
  File "/usr/local/lib/python3.9/site-packages/sqlalchemy/engine/strategies.py", line 54, in create
    u = url.make_url(name_or_url)
  File "/usr/local/lib/python3.9/site-packages/sqlalchemy/engine/url.py", line 229, in make_url
    return _parse_rfc1738_args(name_or_url)
  File "/usr/local/lib/python3.9/site-packages/sqlalchemy/engine/url.py", line 290, in _parse_rfc1738_args
    raise exc.ArgumentError(
sqlalchemy.exc.ArgumentError: Could not parse rfc1738 URL from string ''
[2025-08-03 17:11:31 +0000] [14] [ERROR] Exception in worker process
Traceback (most recent call last):
  File "/usr/local/lib/python3.9/site-packages/gunicorn/arbiter.py", line 583, in spawn_worker
    worker.init_process()
  File "/usr/local/lib/python3.9/site-packages/gunicorn/workers/base.py", line 129, in init_process
    self.load_wsgi()
  File "/usr/local/lib/python3.9/site-packages/gunicorn/workers/base.py", line 138, in load_wsgi
    self.wsgi = self.app.wsgi()
  File "/usr/local/lib/python3.9/site-packages/gunicorn/app/base.py", line 67, in wsgi
    self.callable = self.load()
  File "/usr/local/lib/python3.9/site-packages/psiturk/experiment_server.py", line 48, in load
    return util.import_app("psiturk.experiment:app")
  File "/usr/local/lib/python3.9/site-packages/gunicorn/util.py", line 350, in import_app
    __import__(module)
  File "/usr/local/lib/python3.9/site-packages/psiturk/experiment.py", line 30, in <module>
    from .db import db_session, init_db
  File "/usr/local/lib/python3.9/site-packages/psiturk/db.py", line 28, in <module>
    engine = create_engine(DATABASE, echo=False, pool_recycle=3600)
  File "/usr/local/lib/python3.9/site-packages/sqlalchemy/engine/__init__.py", line 435, in create_engine
    return strategy.create(*args, **kwargs)
  File "/usr/local/lib/python3.9/site-packages/sqlalchemy/engine/strategies.py", line 54, in create
    u = url.make_url(name_or_url)
  File "/usr/local/lib/python3.9/site-packages/sqlalchemy/engine/url.py", line 229, in make_url
    return _parse_rfc1738_args(name_or_url)
  File "/usr/local/lib/python3.9/site-packages/sqlalchemy/engine/url.py", line 290, in _parse_rfc1738_args
    raise exc.ArgumentError(
sqlalchemy.exc.ArgumentError: Could not parse rfc1738 URL from string ''
[2025-08-03 17:11:31 +0000] [16] [ERROR] Exception in worker process
Traceback (most recent call last):
  File "/usr/local/lib/python3.9/site-packages/gunicorn/arbiter.py", line 583, in spawn_worker
    worker.init_process()
  File "/usr/local/lib/python3.9/site-packages/gunicorn/workers/base.py", line 129, in init_process
    self.load_wsgi()
  File "/usr/local/lib/python3.9/site-packages/gunicorn/workers/base.py", line 138, in load_wsgi
    self.wsgi = self.app.wsgi()
  File "/usr/local/lib/python3.9/site-packages/gunicorn/app/base.py", line 67, in wsgi
    self.callable = self.load()
  File "/usr/local/lib/python3.9/site-packages/psiturk/experiment_server.py", line 48, in load
    return util.import_app("psiturk.experiment:app")
  File "/usr/local/lib/python3.9/site-packages/gunicorn/util.py", line 350, in import_app
    __import__(module)
  File "/usr/local/lib/python3.9/site-packages/psiturk/experiment.py", line 30, in <module>
    from .db import db_session, init_db
  File "/usr/local/lib/python3.9/site-packages/psiturk/db.py", line 28, in <module>
    engine = create_engine(DATABASE, echo=False, pool_recycle=3600)
  File "/usr/local/lib/python3.9/site-packages/sqlalchemy/engine/__init__.py", line 435, in create_engine
    return strategy.create(*args, **kwargs)
  File "/usr/local/lib/python3.9/site-packages/sqlalchemy/engine/strategies.py", line 54, in create
    u = url.make_url(name_or_url)
  File "/usr/local/lib/python3.9/site-packages/sqlalchemy/engine/url.py", line 229, in make_url
    return _parse_rfc1738_args(name_or_url)
  File "/usr/local/lib/python3.9/site-packages/sqlalchemy/engine/url.py", line 290, in _parse_rfc1738_args
    raise exc.ArgumentError(
sqlalchemy.exc.ArgumentError: Could not parse rfc1738 URL from string ''
[2025-08-03 17:11:31 +0000] [18] [ERROR] Exception in worker process
Traceback (most recent call last):
  File "/usr/local/lib/python3.9/site-packages/gunicorn/arbiter.py", line 583, in spawn_worker
    worker.init_process()
  File "/usr/local/lib/python3.9/site-packages/gunicorn/workers/base.py", line 129, in init_process
    self.load_wsgi()
  File "/usr/local/lib/python3.9/site-packages/gunicorn/workers/base.py", line 138, in load_wsgi
    self.wsgi = self.app.wsgi()
  File "/usr/local/lib/python3.9/site-packages/gunicorn/app/base.py", line 67, in wsgi
    self.callable = self.load()
  File "/usr/local/lib/python3.9/site-packages/psiturk/experiment_server.py", line 48, in load
    return util.import_app("psiturk.experiment:app")
  File "/usr/local/lib/python3.9/site-packages/gunicorn/util.py", line 350, in import_app
    __import__(module)
  File "/usr/local/lib/python3.9/site-packages/psiturk/experiment.py", line 30, in <module>
    from .db import db_session, init_db
  File "/usr/local/lib/python3.9/site-packages/psiturk/db.py", line 28, in <module>
    engine = create_engine(DATABASE, echo=False, pool_recycle=3600)
  File "/usr/local/lib/python3.9/site-packages/sqlalchemy/engine/__init__.py", line 435, in create_engine
    return strategy.create(*args, **kwargs)
  File "/usr/local/lib/python3.9/site-packages/sqlalchemy/engine/strategies.py", line 54, in create
    u = url.make_url(name_or_url)
  File "/usr/local/lib/python3.9/site-packages/sqlalchemy/engine/url.py", line 229, in make_url
    return _parse_rfc1738_args(name_or_url)
  File "/usr/local/lib/python3.9/site-packages/sqlalchemy/engine/url.py", line 290, in _parse_rfc1738_args
    raise exc.ArgumentError(
sqlalchemy.exc.ArgumentError: Could not parse rfc1738 URL from string ''
[2025-08-03 17:11:31 +0000] [15] [ERROR] Exception in worker process
Traceback (most recent call last):
  File "/usr/local/lib/python3.9/site-packages/gunicorn/arbiter.py", line 583, in spawn_worker
    worker.init_process()
  File "/usr/local/lib/python3.9/site-packages/gunicorn/workers/base.py", line 129, in init_process
    self.load_wsgi()
  File "/usr/local/lib/python3.9/site-packages/gunicorn/workers/base.py", line 138, in load_wsgi
    self.wsgi = self.app.wsgi()
  File "/usr/local/lib/python3.9/site-packages/gunicorn/app/base.py", line 67, in wsgi
    self.callable = self.load()
  File "/usr/local/lib/python3.9/site-packages/psiturk/experiment_server.py", line 48, in load
    return util.import_app("psiturk.experiment:app")
  File "/usr/local/lib/python3.9/site-packages/gunicorn/util.py", line 350, in import_app
    __import__(module)
  File "/usr/local/lib/python3.9/site-packages/psiturk/experiment.py", line 30, in <module>
    from .db import db_session, init_db
  File "/usr/local/lib/python3.9/site-packages/psiturk/db.py", line 28, in <module>
    engine = create_engine(DATABASE, echo=False, pool_recycle=3600)
  File "/usr/local/lib/python3.9/site-packages/sqlalchemy/engine/__init__.py", line 435, in create_engine
    return strategy.create(*args, **kwargs)
  File "/usr/local/lib/python3.9/site-packages/sqlalchemy/engine/strategies.py", line 54, in create
    u = url.make_url(name_or_url)
  File "/usr/local/lib/python3.9/site-packages/sqlalchemy/engine/url.py", line 229, in make_url
    return _parse_rfc1738_args(name_or_url)
  File "/usr/local/lib/python3.9/site-packages/sqlalchemy/engine/url.py", line 290, in _parse_rfc1738_args
    raise exc.ArgumentError(
sqlalchemy.exc.ArgumentError: Could not parse rfc1738 URL from string ''
[2025-08-03 17:11:31 +0000] [21] [ERROR] Exception in worker process
Traceback (most recent call last):
  File "/usr/local/lib/python3.9/site-packages/gunicorn/arbiter.py", line 583, in spawn_worker
    worker.init_process()
  File "/usr/local/lib/python3.9/site-packages/gunicorn/workers/base.py", line 129, in init_process
    self.load_wsgi()
  File "/usr/local/lib/python3.9/site-packages/gunicorn/workers/base.py", line 138, in load_wsgi
    self.wsgi = self.app.wsgi()
  File "/usr/local/lib/python3.9/site-packages/gunicorn/app/base.py", line 67, in wsgi
    self.callable = self.load()
  File "/usr/local/lib/python3.9/site-packages/psiturk/experiment_server.py", line 48, in load
    return util.import_app("psiturk.experiment:app")
  File "/usr/local/lib/python3.9/site-packages/gunicorn/util.py", line 350, in import_app
    __import__(module)
  File "/usr/local/lib/python3.9/site-packages/psiturk/experiment.py", line 30, in <module>
    from .db import db_session, init_db
  File "/usr/local/lib/python3.9/site-packages/psiturk/db.py", line 28, in <module>
    engine = create_engine(DATABASE, echo=False, pool_recycle=3600)
  File "/usr/local/lib/python3.9/site-packages/sqlalchemy/engine/__init__.py", line 435, in create_engine
    return strategy.create(*args, **kwargs)
  File "/usr/local/lib/python3.9/site-packages/sqlalchemy/engine/strategies.py", line 54, in create
    u = url.make_url(name_or_url)
  File "/usr/local/lib/python3.9/site-packages/sqlalchemy/engine/url.py", line 229, in make_url
    return _parse_rfc1738_args(name_or_url)
  File "/usr/local/lib/python3.9/site-packages/sqlalchemy/engine/url.py", line 290, in _parse_rfc1738_args
    raise exc.ArgumentError(
sqlalchemy.exc.ArgumentError: Could not parse rfc1738 URL from string ''
[2025-08-03 17:11:31 +0000] [19] [ERROR] Exception in worker process
Traceback (most recent call last):
  File "/usr/local/lib/python3.9/site-packages/gunicorn/arbiter.py", line 583, in spawn_worker
    worker.init_process()
  File "/usr/local/lib/python3.9/site-packages/gunicorn/workers/base.py", line 129, in init_process
    self.load_wsgi()
  File "/usr/local/lib/python3.9/site-packages/gunicorn/workers/base.py", line 138, in load_wsgi
    self.wsgi = self.app.wsgi()
  File "/usr/local/lib/python3.9/site-packages/gunicorn/app/base.py", line 67, in wsgi
    self.callable = self.load()
  File "/usr/local/lib/python3.9/site-packages/psiturk/experiment_server.py", line 48, in load
    return util.import_app("psiturk.experiment:app")
  File "/usr/local/lib/python3.9/site-packages/gunicorn/util.py", line 350, in import_app
    __import__(module)
  File "/usr/local/lib/python3.9/site-packages/psiturk/experiment.py", line 30, in <module>
    from .db import db_session, init_db
  File "/usr/local/lib/python3.9/site-packages/psiturk/db.py", line 28, in <module>
    engine = create_engine(DATABASE, echo=False, pool_recycle=3600)
  File "/usr/local/lib/python3.9/site-packages/sqlalchemy/engine/__init__.py", line 435, in create_engine
    return strategy.create(*args, **kwargs)
  File "/usr/local/lib/python3.9/site-packages/sqlalchemy/engine/strategies.py", line 54, in create
    u = url.make_url(name_or_url)
  File "/usr/local/lib/python3.9/site-packages/sqlalchemy/engine/url.py", line 229, in make_url
    return _parse_rfc1738_args(name_or_url)
  File "/usr/local/lib/python3.9/site-packages/sqlalchemy/engine/url.py", line 290, in _parse_rfc1738_args
    raise exc.ArgumentError(
sqlalchemy.exc.ArgumentError: Could not parse rfc1738 URL from string ''
[2025-08-03 17:11:31 +0000] [20] [ERROR] Exception in worker process
Traceback (most recent call last):
  File "/usr/local/lib/python3.9/site-packages/gunicorn/arbiter.py", line 583, in spawn_worker
    worker.init_process()
  File "/usr/local/lib/python3.9/site-packages/gunicorn/workers/base.py", line 129, in init_process
    self.load_wsgi()
  File "/usr/local/lib/python3.9/site-packages/gunicorn/workers/base.py", line 138, in load_wsgi
    self.wsgi = self.app.wsgi()
  File "/usr/local/lib/python3.9/site-packages/gunicorn/app/base.py", line 67, in wsgi
    self.callable = self.load()
  File "/usr/local/lib/python3.9/site-packages/psiturk/experiment_server.py", line 48, in load
    return util.import_app("psiturk.experiment:app")
  File "/usr/local/lib/python3.9/site-packages/gunicorn/util.py", line 350, in import_app
    __import__(module)
  File "/usr/local/lib/python3.9/site-packages/psiturk/experiment.py", line 30, in <module>
    from .db import db_session, init_db
  File "/usr/local/lib/python3.9/site-packages/psiturk/db.py", line 28, in <module>
    engine = create_engine(DATABASE, echo=False, pool_recycle=3600)
  File "/usr/local/lib/python3.9/site-packages/sqlalchemy/engine/__init__.py", line 435, in create_engine
    return strategy.create(*args, **kwargs)
  File "/usr/local/lib/python3.9/site-packages/sqlalchemy/engine/strategies.py", line 54, in create
    u = url.make_url(name_or_url)
  File "/usr/local/lib/python3.9/site-packages/sqlalchemy/engine/url.py", line 229, in make_url
    return _parse_rfc1738_args(name_or_url)
  File "/usr/local/lib/python3.9/site-packages/sqlalchemy/engine/url.py", line 290, in _parse_rfc1738_args
    raise exc.ArgumentError(
sqlalchemy.exc.ArgumentError: Could not parse rfc1738 URL from string ''
[2025-08-03 17:11:31 +0000] [26] [ERROR] Exception in worker process
Traceback (most recent call last):
  File "/usr/local/lib/python3.9/site-packages/gunicorn/arbiter.py", line 583, in spawn_worker
    worker.init_process()
  File "/usr/local/lib/python3.9/site-packages/gunicorn/workers/base.py", line 129, in init_process
    self.load_wsgi()
  File "/usr/local/lib/python3.9/site-packages/gunicorn/workers/base.py", line 138, in load_wsgi
    self.wsgi = self.app.wsgi()
  File "/usr/local/lib/python3.9/site-packages/gunicorn/app/base.py", line 67, in wsgi
    self.callable = self.load()
  File "/usr/local/lib/python3.9/site-packages/psiturk/experiment_server.py", line 48, in load
    return util.import_app("psiturk.experiment:app")
  File "/usr/local/lib/python3.9/site-packages/gunicorn/util.py", line 350, in import_app
    __import__(module)
  File "/usr/local/lib/python3.9/site-packages/psiturk/experiment.py", line 30, in <module>
    from .db import db_session, init_db
  File "/usr/local/lib/python3.9/site-packages/psiturk/db.py", line 28, in <module>
    engine = create_engine(DATABASE, echo=False, pool_recycle=3600)
  File "/usr/local/lib/python3.9/site-packages/sqlalchemy/engine/__init__.py", line 435, in create_engine
    return strategy.create(*args, **kwargs)
  File "/usr/local/lib/python3.9/site-packages/sqlalchemy/engine/strategies.py", line 54, in create
    u = url.make_url(name_or_url)
  File "/usr/local/lib/python3.9/site-packages/sqlalchemy/engine/url.py", line 229, in make_url
    return _parse_rfc1738_args(name_or_url)
  File "/usr/local/lib/python3.9/site-packages/sqlalchemy/engine/url.py", line 290, in _parse_rfc1738_args
    raise exc.ArgumentError(
sqlalchemy.exc.ArgumentError: Could not parse rfc1738 URL from string ''
[2025-08-03 17:11:31 +0000] [24] [ERROR] Exception in worker process
Traceback (most recent call last):
  File "/usr/local/lib/python3.9/site-packages/gunicorn/arbiter.py", line 583, in spawn_worker
    worker.init_process()
  File "/usr/local/lib/python3.9/site-packages/gunicorn/workers/base.py", line 129, in init_process
    self.load_wsgi()
  File "/usr/local/lib/python3.9/site-packages/gunicorn/workers/base.py", line 138, in load_wsgi
    self.wsgi = self.app.wsgi()
  File "/usr/local/lib/python3.9/site-packages/gunicorn/app/base.py", line 67, in wsgi
    self.callable = self.load()
  File "/usr/local/lib/python3.9/site-packages/psiturk/experiment_server.py", line 48, in load
    return util.import_app("psiturk.experiment:app")
  File "/usr/local/lib/python3.9/site-packages/gunicorn/util.py", line 350, in import_app
    __import__(module)
  File "/usr/local/lib/python3.9/site-packages/psiturk/experiment.py", line 30, in <module>
    from .db import db_session, init_db
  File "/usr/local/lib/python3.9/site-packages/psiturk/db.py", line 28, in <module>
    engine = create_engine(DATABASE, echo=False, pool_recycle=3600)
  File "/usr/local/lib/python3.9/site-packages/sqlalchemy/engine/__init__.py", line 435, in create_engine
    return strategy.create(*args, **kwargs)
  File "/usr/local/lib/python3.9/site-packages/sqlalchemy/engine/strategies.py", line 54, in create
    u = url.make_url(name_or_url)
  File "/usr/local/lib/python3.9/site-packages/sqlalchemy/engine/url.py", line 229, in make_url
    return _parse_rfc1738_args(name_or_url)
  File "/usr/local/lib/python3.9/site-packages/sqlalchemy/engine/url.py", line 290, in _parse_rfc1738_args
    raise exc.ArgumentError(
sqlalchemy.exc.ArgumentError: Could not parse rfc1738 URL from string ''
[2025-08-03 17:11:31 +0000] [25] [ERROR] Exception in worker process
Traceback (most recent call last):
  File "/usr/local/lib/python3.9/site-packages/gunicorn/arbiter.py", line 583, in spawn_worker
    worker.init_process()
  File "/usr/local/lib/python3.9/site-packages/gunicorn/workers/base.py", line 129, in init_process
    self.load_wsgi()
  File "/usr/local/lib/python3.9/site-packages/gunicorn/workers/base.py", line 138, in load_wsgi
    self.wsgi = self.app.wsgi()
  File "/usr/local/lib/python3.9/site-packages/gunicorn/app/base.py", line 67, in wsgi
    self.callable = self.load()
  File "/usr/local/lib/python3.9/site-packages/psiturk/experiment_server.py", line 48, in load
    return util.import_app("psiturk.experiment:app")
  File "/usr/local/lib/python3.9/site-packages/gunicorn/util.py", line 350, in import_app
    __import__(module)
  File "/usr/local/lib/python3.9/site-packages/psiturk/experiment.py", line 30, in <module>
    from .db import db_session, init_db
  File "/usr/local/lib/python3.9/site-packages/psiturk/db.py", line 28, in <module>
    engine = create_engine(DATABASE, echo=False, pool_recycle=3600)
  File "/usr/local/lib/python3.9/site-packages/sqlalchemy/engine/__init__.py", line 435, in create_engine
    return strategy.create(*args, **kwargs)
  File "/usr/local/lib/python3.9/site-packages/sqlalchemy/engine/strategies.py", line 54, in create
    u = url.make_url(name_or_url)
  File "/usr/local/lib/python3.9/site-packages/sqlalchemy/engine/url.py", line 229, in make_url
    return _parse_rfc1738_args(name_or_url)
  File "/usr/local/lib/python3.9/site-packages/sqlalchemy/engine/url.py", line 290, in _parse_rfc1738_args
    raise exc.ArgumentError(
sqlalchemy.exc.ArgumentError: Could not parse rfc1738 URL from string ''
[2025-08-03 17:11:32 +0000] [22] [ERROR] Exception in worker process
Traceback (most recent call last):
  File "/usr/local/lib/python3.9/site-packages/gunicorn/arbiter.py", line 583, in spawn_worker
    worker.init_process()
  File "/usr/local/lib/python3.9/site-packages/gunicorn/workers/base.py", line 129, in init_process
    self.load_wsgi()
  File "/usr/local/lib/python3.9/site-packages/gunicorn/workers/base.py", line 138, in load_wsgi
    self.wsgi = self.app.wsgi()
  File "/usr/local/lib/python3.9/site-packages/gunicorn/app/base.py", line 67, in wsgi
    self.callable = self.load()
  File "/usr/local/lib/python3.9/site-packages/psiturk/experiment_server.py", line 48, in load
    return util.import_app("psiturk.experiment:app")
  File "/usr/local/lib/python3.9/site-packages/gunicorn/util.py", line 350, in import_app
    __import__(module)
  File "/usr/local/lib/python3.9/site-packages/psiturk/experiment.py", line 30, in <module>
    from .db import db_session, init_db
  File "/usr/local/lib/python3.9/site-packages/psiturk/db.py", line 28, in <module>
    engine = create_engine(DATABASE, echo=False, pool_recycle=3600)
  File "/usr/local/lib/python3.9/site-packages/sqlalchemy/engine/__init__.py", line 435, in create_engine
    return strategy.create(*args, **kwargs)
  File "/usr/local/lib/python3.9/site-packages/sqlalchemy/engine/strategies.py", line 54, in create
    u = url.make_url(name_or_url)
  File "/usr/local/lib/python3.9/site-packages/sqlalchemy/engine/url.py", line 229, in make_url
    return _parse_rfc1738_args(name_or_url)
  File "/usr/local/lib/python3.9/site-packages/sqlalchemy/engine/url.py", line 290, in _parse_rfc1738_args
    raise exc.ArgumentError(
sqlalchemy.exc.ArgumentError: Could not parse rfc1738 URL from string ''
[2025-08-03 17:26:24 +0000] [10] [ERROR] Exception in worker process
Traceback (most recent call last):
  File "/usr/local/lib/python3.9/site-packages/gunicorn/arbiter.py", line 583, in spawn_worker
    worker.init_process()
  File "/usr/local/lib/python3.9/site-packages/gunicorn/workers/base.py", line 129, in init_process
    self.load_wsgi()
  File "/usr/local/lib/python3.9/site-packages/gunicorn/workers/base.py", line 138, in load_wsgi
    self.wsgi = self.app.wsgi()
  File "/usr/local/lib/python3.9/site-packages/gunicorn/app/base.py", line 67, in wsgi
    self.callable = self.load()
  File "/usr/local/lib/python3.9/site-packages/psiturk/experiment_server.py", line 48, in load
    return util.import_app("psiturk.experiment:app")
  File "/usr/local/lib/python3.9/site-packages/gunicorn/util.py", line 350, in import_app
    __import__(module)
  File "/usr/local/lib/python3.9/site-packages/psiturk/experiment.py", line 60, in <module>
    app = Flask("Experiment_Server")
  File "/usr/local/lib/python3.9/site-packages/flask/app.py", line 559, in __init__
    self.add_url_rule(
  File "/usr/local/lib/python3.9/site-packages/flask/app.py", line 67, in wrapper_func
    return f(self, *args, **kwargs)
  File "/usr/local/lib/python3.9/site-packages/flask/app.py", line 1217, in add_url_rule
    self.url_map.add(rule)
  File "/usr/local/lib/python3.9/site-packages/werkzeug/routing.py", line 1388, in add
    rule.bind(self)
  File "/usr/local/lib/python3.9/site-packages/werkzeug/routing.py", line 730, in bind
    self.compile()
  File "/usr/local/lib/python3.9/site-packages/werkzeug/routing.py", line 794, in compile
    self._build = self._compile_builder(False).__get__(self, None)
  File "/usr/local/lib/python3.9/site-packages/werkzeug/routing.py", line 951, in _compile_builder
    code = compile(module, "<werkzeug routing>", "exec")
TypeError: required field "type_ignores" missing from Module
[2025-08-03 17:29:26 +0000] [11] [ERROR] Exception in worker process
Traceback (most recent call last):
  File "/usr/local/lib/python3.9/site-packages/gunicorn/arbiter.py", line 583, in spawn_worker
    worker.init_process()
  File "/usr/local/lib/python3.9/site-packages/gunicorn/workers/base.py", line 129, in init_process
    self.load_wsgi()
  File "/usr/local/lib/python3.9/site-packages/gunicorn/workers/base.py", line 138, in load_wsgi
    self.wsgi = self.app.wsgi()
  File "/usr/local/lib/python3.9/site-packages/gunicorn/app/base.py", line 67, in wsgi
    self.callable = self.load()
  File "/usr/local/lib/python3.9/site-packages/psiturk/experiment_server.py", line 48, in load
    return util.import_app("psiturk.experiment:app")
  File "/usr/local/lib/python3.9/site-packages/gunicorn/util.py", line 350, in import_app
    __import__(module)
  File "/usr/local/lib/python3.9/site-packages/psiturk/experiment.py", line 60, in <module>
    app = Flask("Experiment_Server")
  File "/usr/local/lib/python3.9/site-packages/flask/app.py", line 559, in __init__
    self.add_url_rule(
  File "/usr/local/lib/python3.9/site-packages/flask/app.py", line 67, in wrapper_func
    return f(self, *args, **kwargs)
  File "/usr/local/lib/python3.9/site-packages/flask/app.py", line 1217, in add_url_rule
    self.url_map.add(rule)
  File "/usr/local/lib/python3.9/site-packages/werkzeug/routing.py", line 1388, in add
    rule.bind(self)
  File "/usr/local/lib/python3.9/site-packages/werkzeug/routing.py", line 730, in bind
    self.compile()
  File "/usr/local/lib/python3.9/site-packages/werkzeug/routing.py", line 794, in compile
    self._build = self._compile_builder(False).__get__(self, None)
  File "/usr/local/lib/python3.9/site-packages/werkzeug/routing.py", line 951, in _compile_builder
    code = compile(module, "<werkzeug routing>", "exec")
TypeError: required field "type_ignores" missing from Module
[2025-08-03 17:57:33 +0000] [10] [ERROR] Exception in worker process
Traceback (most recent call last):
  File "/usr/local/lib/python3.9/site-packages/gunicorn/arbiter.py", line 583, in spawn_worker
    worker.init_process()
  File "/usr/local/lib/python3.9/site-packages/gunicorn/workers/base.py", line 129, in init_process
    self.load_wsgi()
  File "/usr/local/lib/python3.9/site-packages/gunicorn/workers/base.py", line 138, in load_wsgi
    self.wsgi = self.app.wsgi()
  File "/usr/local/lib/python3.9/site-packages/gunicorn/app/base.py", line 67, in wsgi
    self.callable = self.load()
  File "/usr/local/lib/python3.9/site-packages/psiturk/experiment_server.py", line 48, in load
    return util.import_app("psiturk.experiment:app")
  File "/usr/local/lib/python3.9/site-packages/gunicorn/util.py", line 350, in import_app
    __import__(module)
  File "/usr/local/lib/python3.9/site-packages/psiturk/experiment.py", line 60, in <module>
    app = Flask("Experiment_Server")
  File "/usr/local/lib/python3.9/site-packages/flask/app.py", line 559, in __init__
    self.add_url_rule(
  File "/usr/local/lib/python3.9/site-packages/flask/app.py", line 67, in wrapper_func
    return f(self, *args, **kwargs)
  File "/usr/local/lib/python3.9/site-packages/flask/app.py", line 1217, in add_url_rule
    self.url_map.add(rule)
  File "/usr/local/lib/python3.9/site-packages/werkzeug/routing.py", line 1388, in add
    rule.bind(self)
  File "/usr/local/lib/python3.9/site-packages/werkzeug/routing.py", line 730, in bind
    self.compile()
  File "/usr/local/lib/python3.9/site-packages/werkzeug/routing.py", line 794, in compile
    self._build = self._compile_builder(False).__get__(self, None)
  File "/usr/local/lib/python3.9/site-packages/werkzeug/routing.py", line 951, in _compile_builder
    code = compile(module, "<werkzeug routing>", "exec")
TypeError: required field "type_ignores" missing from Module
